
PLAY [Docker model run && show output] *****************************************

TASK [Gathering Facts] *********************************************************
ok: [rpi6402]

TASK [model train] *************************************************************
fatal: [rpi6402]: FAILED! => {"changed": true, "cmd": ["docker", "exec", "RunTest_pd_model", "python", "home/model.py", "--input", "/home/data/test.jpg", "--mod", "train"], "delta": "0:00:10.845580", "end": "2023-05-16 18:15:41.918892", "msg": "non-zero return code", "rc": 1, "start": "2023-05-16 18:15:31.073312", "stderr": "Ultralytics YOLOv8.0.103 üöÄ Python-3.8.15 torch-2.0.1 CPU\n\u001b[34m\u001b[1myolo/engine/trainer: \u001b[0mtask=detect, mode=train, model=/home/pd_base.pt, data=/home/data/test.jpg, epochs=10, patience=50, batch=8, imgsz=640, save=True, save_period=-1, cache=False, device=None, workers=8, project=None, name=None, exist_ok=False, pretrained=False, optimizer=SGD, verbose=True, seed=0, deterministic=True, single_cls=False, rect=False, cos_lr=False, close_mosaic=0, resume=False, amp=True, overlap_mask=True, mask_ratio=4, dropout=0.0, val=True, split=val, save_json=False, save_hybrid=False, conf=None, iou=0.7, max_det=300, half=False, dnn=False, plots=True, source=None, show=False, save_txt=False, save_conf=False, save_crop=False, show_labels=True, show_conf=True, vid_stride=1, line_width=None, visualize=False, augment=False, agnostic_nms=False, classes=None, retina_masks=False, boxes=True, format=torchscript, keras=False, optimize=False, int8=False, dynamic=False, simplify=False, opset=None, workspace=4, nms=False, lr0=0.01, lrf=0.01, momentum=0.937, weight_decay=0.0005, warmup_epochs=3.0, warmup_momentum=0.8, warmup_bias_lr=0.1, box=7.5, cls=0.5, dfl=1.5, pose=12.0, kobj=1.0, label_smoothing=0.0, nbs=64, hsv_h=0.015, hsv_s=0.7, hsv_v=0.4, degrees=0.0, translate=0.1, scale=0.5, shear=0.0, perspective=0.0, flipud=0.0, fliplr=0.5, mosaic=1.0, mixup=0.0, copy_paste=0.0, cfg=None, v5loader=False, tracker=botsort.yaml, save_dir=runs/detect/train2\nTraceback (most recent call last):\n  File \"/usr/local/lib/python3.8/site-packages/ultralytics/yolo/engine/trainer.py\", line 122, in __init__\n    self.data = check_det_dataset(self.args.data)\n  File \"/usr/local/lib/python3.8/site-packages/ultralytics/yolo/data/utils.py\", line 206, in check_det_dataset\n    data = yaml_load(data, append_filename=True)  # dictionary\n  File \"/usr/local/lib/python3.8/site-packages/ultralytics/yolo/utils/__init__.py\", line 290, in yaml_load\n    return {**yaml.safe_load(s), 'yaml_file': str(file)} if append_filename else yaml.safe_load(s)\n  File \"/usr/local/lib/python3.8/site-packages/yaml/__init__.py\", line 125, in safe_load\n    return load(stream, SafeLoader)\n  File \"/usr/local/lib/python3.8/site-packages/yaml/__init__.py\", line 81, in load\n    return loader.get_single_data()\n  File \"/usr/local/lib/python3.8/site-packages/yaml/constructor.py\", line 49, in get_single_data\n    node = self.get_single_node()\n  File \"/usr/local/lib/python3.8/site-packages/yaml/composer.py\", line 36, in get_single_node\n    document = self.compose_document()\n  File \"/usr/local/lib/python3.8/site-packages/yaml/composer.py\", line 58, in compose_document\n    self.get_event()\n  File \"/usr/local/lib/python3.8/site-packages/yaml/parser.py\", line 118, in get_event\n    self.current_event = self.state()\n  File \"/usr/local/lib/python3.8/site-packages/yaml/parser.py\", line 193, in parse_document_end\n    token = self.peek_token()\n  File \"/usr/local/lib/python3.8/site-packages/yaml/scanner.py\", line 129, in peek_token\n    self.fetch_more_tokens()\n  File \"/usr/local/lib/python3.8/site-packages/yaml/scanner.py\", line 258, in fetch_more_tokens\n    raise ScannerError(\"while scanning for the next token\", None,\nyaml.scanner.ScannerError: while scanning for the next token\nfound character '\\t' that cannot start any token\n  in \"<unicode string>\", line 2, column 88:\n     ... 150231Uv~(HHJFIFHHAdobe_CMAdobed\t\t\t\n                                         ^\n\nThe above exception was the direct cause of the following exception:\n\nTraceback (most recent call last):\n  File \"home/model.py\", line 127, in <module>\n    pd.train(\n  File \"home/model.py\", line 22, in train\n    self.model.train(\n  File \"/usr/local/lib/python3.8/site-packages/ultralytics/yolo/engine/model.py\", line 366, in train\n    self.trainer = TASK_MAP[self.task][1](overrides=overrides, _callbacks=self.callbacks)\n  File \"/usr/local/lib/python3.8/site-packages/ultralytics/yolo/engine/trainer.py\", line 126, in __init__\n    raise RuntimeError(emojis(f\"Dataset '{clean_url(self.args.data)}' error ‚ùå {e}\")) from e\nRuntimeError: Dataset '/home/data/test.jpg' error ‚ùå while scanning for the next token\nfound character '\\t' that cannot start any token\n  in \"<unicode string>\", line 2, column 88:\n     ... 150231Uv~(HHJFIFHHAdobe_CMAdobed\t\t\t\n                                         ^", "stderr_lines": ["Ultralytics YOLOv8.0.103 üöÄ Python-3.8.15 torch-2.0.1 CPU", "\u001b[34m\u001b[1myolo/engine/trainer: \u001b[0mtask=detect, mode=train, model=/home/pd_base.pt, data=/home/data/test.jpg, epochs=10, patience=50, batch=8, imgsz=640, save=True, save_period=-1, cache=False, device=None, workers=8, project=None, name=None, exist_ok=False, pretrained=False, optimizer=SGD, verbose=True, seed=0, deterministic=True, single_cls=False, rect=False, cos_lr=False, close_mosaic=0, resume=False, amp=True, overlap_mask=True, mask_ratio=4, dropout=0.0, val=True, split=val, save_json=False, save_hybrid=False, conf=None, iou=0.7, max_det=300, half=False, dnn=False, plots=True, source=None, show=False, save_txt=False, save_conf=False, save_crop=False, show_labels=True, show_conf=True, vid_stride=1, line_width=None, visualize=False, augment=False, agnostic_nms=False, classes=None, retina_masks=False, boxes=True, format=torchscript, keras=False, optimize=False, int8=False, dynamic=False, simplify=False, opset=None, workspace=4, nms=False, lr0=0.01, lrf=0.01, momentum=0.937, weight_decay=0.0005, warmup_epochs=3.0, warmup_momentum=0.8, warmup_bias_lr=0.1, box=7.5, cls=0.5, dfl=1.5, pose=12.0, kobj=1.0, label_smoothing=0.0, nbs=64, hsv_h=0.015, hsv_s=0.7, hsv_v=0.4, degrees=0.0, translate=0.1, scale=0.5, shear=0.0, perspective=0.0, flipud=0.0, fliplr=0.5, mosaic=1.0, mixup=0.0, copy_paste=0.0, cfg=None, v5loader=False, tracker=botsort.yaml, save_dir=runs/detect/train2", "Traceback (most recent call last):", "  File \"/usr/local/lib/python3.8/site-packages/ultralytics/yolo/engine/trainer.py\", line 122, in __init__", "    self.data = check_det_dataset(self.args.data)", "  File \"/usr/local/lib/python3.8/site-packages/ultralytics/yolo/data/utils.py\", line 206, in check_det_dataset", "    data = yaml_load(data, append_filename=True)  # dictionary", "  File \"/usr/local/lib/python3.8/site-packages/ultralytics/yolo/utils/__init__.py\", line 290, in yaml_load", "    return {**yaml.safe_load(s), 'yaml_file': str(file)} if append_filename else yaml.safe_load(s)", "  File \"/usr/local/lib/python3.8/site-packages/yaml/__init__.py\", line 125, in safe_load", "    return load(stream, SafeLoader)", "  File \"/usr/local/lib/python3.8/site-packages/yaml/__init__.py\", line 81, in load", "    return loader.get_single_data()", "  File \"/usr/local/lib/python3.8/site-packages/yaml/constructor.py\", line 49, in get_single_data", "    node = self.get_single_node()", "  File \"/usr/local/lib/python3.8/site-packages/yaml/composer.py\", line 36, in get_single_node", "    document = self.compose_document()", "  File \"/usr/local/lib/python3.8/site-packages/yaml/composer.py\", line 58, in compose_document", "    self.get_event()", "  File \"/usr/local/lib/python3.8/site-packages/yaml/parser.py\", line 118, in get_event", "    self.current_event = self.state()", "  File \"/usr/local/lib/python3.8/site-packages/yaml/parser.py\", line 193, in parse_document_end", "    token = self.peek_token()", "  File \"/usr/local/lib/python3.8/site-packages/yaml/scanner.py\", line 129, in peek_token", "    self.fetch_more_tokens()", "  File \"/usr/local/lib/python3.8/site-packages/yaml/scanner.py\", line 258, in fetch_more_tokens", "    raise ScannerError(\"while scanning for the next token\", None,", "yaml.scanner.ScannerError: while scanning for the next token", "found character '\\t' that cannot start any token", "  in \"<unicode string>\", line 2, column 88:", "     ... 150231Uv~(HHJFIFHHAdobe_CMAdobed\t\t\t", "                                         ^", "", "The above exception was the direct cause of the following exception:", "", "Traceback (most recent call last):", "  File \"home/model.py\", line 127, in <module>", "    pd.train(", "  File \"home/model.py\", line 22, in train", "    self.model.train(", "  File \"/usr/local/lib/python3.8/site-packages/ultralytics/yolo/engine/model.py\", line 366, in train", "    self.trainer = TASK_MAP[self.task][1](overrides=overrides, _callbacks=self.callbacks)", "  File \"/usr/local/lib/python3.8/site-packages/ultralytics/yolo/engine/trainer.py\", line 126, in __init__", "    raise RuntimeError(emojis(f\"Dataset '{clean_url(self.args.data)}' error ‚ùå {e}\")) from e", "RuntimeError: Dataset '/home/data/test.jpg' error ‚ùå while scanning for the next token", "found character '\\t' that cannot start any token", "  in \"<unicode string>\", line 2, column 88:", "     ... 150231Uv~(HHJFIFHHAdobe_CMAdobed\t\t\t", "                                         ^"], "stdout": "", "stdout_lines": []}

PLAY RECAP *********************************************************************
rpi6402                    : ok=1    changed=0    unreachable=0    failed=1    skipped=0    rescued=0    ignored=0   

